Workbook

Sheet List
A1: 기준정보 List
A2: 순번 | B2: Master / 기준 명 | C2: 담당 | D2: Sheet | E2: 버튼 | J2: 설명
E3: 조회 | F3: 수정 | G3: 엑셀 | H3: 저장 | I3: 닫기
A4: 1 | B4: 제품군/세부제품 코드 Master | D4: 1 | E4: ● | F4: ● | G4: ● | H4: ● | I4: ●
A5: 2 | B5: OEM 정보 Master | D5: 2 | E5: ● | F5: ● | G5: ● | H5: ● | I5: ●
A6: 3 | B6: 국가 정보 Master | D6: 2 | E6: ● | F6: ● | G6: ● | H6: ● | I6: ●
A7: 4 | B7: 법인 정보 Master | D7: 2 | E7: ● | F7: ● | G7: ● | H7: ● | I7: ●
A8: 5 | B8: 공장 정보 Master | D8: 2 | E8: ● | F8: ● | G8: ● | H8: ● | I8: ●
A9: 6 | B9: 수주탈락 사유 Master | D9: 3 | E9: ● | F9: ● | G9: ● | H9: ● | I9: ●
A10: 7 | B10: 견적표준일정 | D10: 4 | E10: ● | F10: ● | G10: ● | H10: ● | I10: ●
A11: 8 | B11: 목표표준일정 | D11: 4 | E11: ● | F11: ● | G11: ● | H11: ● | I11: ●
A12: 9 | B12: 손익 계정 관리 | D12: 5 | E12: ● | F12: ● | G12: ● | H12: ● | I12: ●
A13: 10 | B13: 부서 Master | D13: 6 | E13: ● | F13: ● | G13: ● | H13: ● | I13: ●
A14: 11 | B14: 사용자 정보 Master | D14: 6 | E14: ● | F14: ● | G14: ● | H14: ● | I14: ●
A15: 12 | B15: 생산 라인 정보 | D15: 7 | E15: ● | F15: ● | G15: ● | H15: ● | I15: ●
... A18: 15 | B18: 사업실적 정보 | D18: 8 | E18: ● | F18: ● | G18: ● | H18: ● | I18: ●
A19: 16 | E19: ● | F19: ● | G19: ● | H19: ● | I19: ●

Sheet 견적

Sheet 손익계산서
B2: 1. 기본 정보
C4: 손익계산서
C6: 1307-TM-E01 | F6: 2014 | G6: 2015 | H6: 2016 | I6: 2017 | J6: 2018 | K6: 2019 | L6: 2020 | M6: 2021 | N6: 합계
C7: 수량 | F7: =RFQ정보!C28 -> 300 | G7: =RFQ정보!D28 -> 1000 | H7: =RFQ정보!E28 -> 1200 | I7: =RFQ정보!F28 -> 1500 | J7: =RFQ정보!G28 -> 1800 | K7: =RFQ정보!H28 -> 2000 | L7: =RFQ정보!I28 -> 2000 | M7: =RFQ정보!J28 -> 1500 | N7: =SUM(F7:M7) -> 11300
F10: 2014 | G10: 2015 | H10: 2016 | I10: 2017 | J10: 2018 | K10: 2019 | L10: 2020 | M10: 2021 | N10: 합계
C11: 판가(견적기준가) | F11: =RFQ정보!C49 -> 180000000 | G11: =RFQ정보!D49 -> 594000000 | H11: =RFQ정보!E49 -> 705672000 | I11: =RFQ정보!F49 -> 873269100 | J11: =RFQ정보!G49 -> 1047922920 | K11: =RFQ정보!H49 -> 1164358800 | L11: =RFQ정보!I49 -> 1164358800 | M11: =RFQ정보!J49 -> 873269100 | N11: =SUM(F11:M11) -> 6602850720
C12: 매출원가 | F12: =F13+F14+F16 -> 1.6113813e+08 | G12: =G13+G14+G16 -> 5.2011741e+08 | H12: =H13+H14+H16 -> 6.1585073e+08 | I12: =I13+I14+I16 -> 7.5960573e+08 | J12: =J13+J14+J16 -> 9.0982598e+08 | K12: =K13+K14+K16 -> 1.0113731e+09 | L12: =L13+L14+L16 -> 1.0141797e+09 | M12: =M13+M14+M16 -> 7.6784118e+08 | N12: =SUM(F12:M12) -> 5.759932e+09
C13: 재료비 | F13: ='master list(견적BOM)'!C25 -> 1.4356926e+08 | G13: ='master list(견적BOM)'!D25 -> 4.7377856e+08 | H13: ='master list(견적BOM)'!E25 -> 5.6284893e+08 | I13: ='master list(견적BOM)'!F25 -> 6.9652556e+08 | J13: ='master list(견적BOM)'!G25 -> 8.3583067e+08 | K13: ='master list(견적BOM)'!H25 -> 9.2870074e+08 | L13: ='master list(견적BOM)'!I25 -> 9.2870074e+08 | M13: ='master list(견적BOM)'!J25 -> 6.9652556e+08 | N13: =SUM(F13:M13) -> 5.26648e+09
C14: 노무비 | F14: =SUM(F15:F15) -> 3844968.8 | G14: =SUM(G15:G15) -> 13457391 | H14: =SUM(H15:H15) -> 16956312 | I14: =SUM(I15:I15) -> 22255160 | J14: =SUM(J15:J15) -> 28041501 | K14: =SUM(K15:K15) -> 32715085 | L14: =SUM(L15:L15) -> 34350839 | M14: =SUM(M15:M15) -> 27051286 | N14: =SUM(F14:M14) -> 1.7867254e+08
E15: 노무비 | F15: ='원가산출 정보'!D50 -> 3844968.8 | G15: ='원가산출 정보'!E50 -> 13457391 | H15: ='원가산출 정보'!F50 -> 16956312 | I15: ='원가산출 정보'!G50 -> 22255160 | J15: ='원가산출 정보'!H50 -> 28041501 | K15: ='원가산출 정보'!I50 -> 32715085 | L15: ='원가산출 정보'!J50 -> 34350839 | M15: ='원가산출 정보'!K50 -> 27051286
C16: 경비 | F16: =SUM(F17:F21) -> 13723903 | G16: =SUM(G17:G21) -> 32881457 | H16: =SUM(H17:H21) -> 36045488 | I16: =SUM(I17:I21) -> 40825010 | J16: =SUM(J17:J21) -> 45953815 | K16: =SUM(K17:K21) -> 49957312 | L16: =SUM(L17:L21) -> 51128154 | M16: =SUM(M17:M21) -> 44264342 | N16: =SUM(F16:M16) -> 3.1477948e+08
E17: 생산직접비 | F17: ='원가산출 정보'!D51 -> 1182664.7 | G17: ='원가산출 정보'!E51 -> 4099904.3 | H17: ='원가산출 정보'!F51 -> 5116680.6 | I17: ='원가산출 정보'!G51 -> 6651684.7 | J17: ='원가산출 정보'!H51 -> 8301302.6 | K17: ='원가산출 정보'!I51 -> 9592616.3 | L17: ='원가산출 정보'!J51 -> 9976320.9 | M17: ='원가산출 정보'!K51 -> 7781530.3
E18: 감가상각비 | F18: ='원가산출 정보'!D52 -> 10300000 | G18: ='원가산출 정보'!E52 -> 21000000 | H18: ='원가산출 정보'!F52 -> 21200000 | I18: ='원가산출 정보'!G52 -> 21500000 | J18: ='원가산출 정보'!H52 -> 21800000 | K18: ='원가산출 정보'!I52 -> 22000000 | L18: ='원가산출 정보'!J52 -> 22000000 | M18: ='원가산출 정보'!K52 -> 21500000
E19: 외주가공비 | F19: =1000*F7 -> 300000 | G19: =1000*G7 -> 1000000 | H19: =1000*H7 -> 1200000 | I19: =1000*I7 -> 1500000 | J19: =1000*J7 -> 1800000 | K19: =1000*K7 -> 2000000 | L19: =1000*L7 -> 2000000 | M19: =1000*M7 -> 1500000
E20: 인건비성경비 | F20: ='원가산출 정보'!D53 -> 1557832.5 | G20: ='원가산출 정보'!E53 -> 5452413.8 | H20: ='원가산출 정보'!F53 -> 6870041.3 | I20: ='원가산출 정보'!G53 -> 9016929.2 | J20: ='원가산출 정보'!H53 -> 11361331 | K20: ='원가산출 정보'!I53 -> 13254886 | L20: ='원가산출 정보'!J53 -> 13917630 | M20: ='원가산출 정보'!K53 -> 10960134
E21: 기타경비 | F21: ='원가산출 정보'!D54 -> 383405.57 | G21: ='원가산출 정보'!E54 -> 1329139.3 | H21: ='원가산출 정보'!F54 -> 1658765.8 | I21: ='원가산출 정보'!G54 -> 2156395.6 | J21: ='원가산출 정보'!H54 -> 2691181.7 | K21: ='원가산출 정보'!I54 -> 3109810 | L21: ='원가산출 정보'!J54 -> 3234202.4 | M21: ='원가산출 정보'!K54 -> 2522677.9
C22: 판매관리비 | F22: =F23+F24 -> 4356000 | G22: =G23+G24 -> 14374800 | H22: =H23+H24 -> 17077262 | I22: =I23+I24 -> 21133112 | J22: =J23+J24 -> 25359735 | K22: =K23+K24 -> 28177483 | L22: =L23+L24 -> 28177483 | M22: =M23+M24 -> 21133112 | N22: =SUM(F22:M22) -> 1.5978899e+08
E23: 판관인건비 | F23: =F$11*기준정보!$H$7 -> 900000 | G23: =G$11*기준정보!$H$7 -> 2970000 | H23: =H$11*기준정보!$H$7 -> 3528360 | I23: =I$11*기준정보!$H$7 -> 4366345.5 | J23: =J$11*기준정보!$H$7 -> 5239614.6 | K23: =K$11*기준정보!$H$7 -> 5821794 | L23: =L$11*기준정보!$H$7 -> 5821794 | M23: =M$11*기준정보!$H$7 -> 4366345.5
D24: 판매비 | F24: =SUM(F25:F32) -> 3456000 | G24: =SUM(G25:G32) -> 11404800 | H24: =SUM(H25:H32) -> 13548902 | I24: =SUM(I25:I32) -> 16766767 | J24: =SUM(J25:J32) -> 20120120 | K24: =SUM(K25:K32) -> 22355689 | L24: =SUM(L25:L32) -> 22355689 | M24: =SUM(M25:M32) -> 16766767
E25: 운반비 | F25: =F$11*기준정보!$H8 -> 540000 | G25: =G$11*기준정보!$H8 -> 1782000 | H25: =H$11*기준정보!$H8 -> 2117016 | I25: =I$11*기준정보!$H8 -> 2619807.3 | J25: =J$11*기준정보!$H8 -> 3143768.8 | K25: =K$11*기준정보!$H8 -> 3493076.4 | L25: =L$11*기준정보!$H8 -> 3493076.4 | M25: =M$11*기준정보!$H8 -> 2619807.3
E26: 수출비 | F26: =F$11*기준정보!$H9 -> 180000 | G26: =G$11*기준정보!$H9 -> 594000 | H26: =H$11*기준정보!$H9 -> 705672 | I26: =I$11*기준정보!$H9 -> 873269.1 | J26: =J$11*기준정보!$H9 -> 1047922.9 | K26: =K$11*기준정보!$H9 -> 1164358.8 | L26: =L$11*기준정보!$H9 -> 1164358.8 | M26: =M$11*기준정보!$H9 -> 873269.1
E27: 품질보증비 | F27: =F$11*기준정보!$H10 -> 540000 | G27: =G$11*기준정보!$H10 -> 1782000 | H27: =H$11*기준정보!$H10 -> 2117016 | I27: =I$11*기준정보!$H10 -> 2619807.3 | J27: =J$11*기준정보!$H10 -> 3143768.8 | K27: =K$11*기준정보!$H10 -> 3493076.4 | L27: =L$11*기준정보!$H10 -> 3493076.4 | M27: =M$11*기준정보!$H10 -> 2619807.3
E28: 광고선전비 | F28: =F$11*기준정보!$H11 -> 360000 | G28: =G$11*기준정보!$H11 -> 1188000 | H28: =H$11*기준정보!$H11 -> 1411344 | I28: =I$11*기준정보!$H11 -> 1746538.2 | J28: =J$11*기준정보!$H11 -> 2095845.8 | K28: =K$11*기준정보!$H11 -> 2328717.6 | L28: =L$11*기준정보!$H11 -> 2328717.6 | M28: =M$11*기준정보!$H11 -> 1746538.2
E29: 연구비 | F29: =F$11*기준정보!$H12 -> 90000 | G29: =G$11*기준정보!$H12 -> 297000 | H29: =H$11*기준정보!$H12 -> 352836 | I29: =I$11*기준정보!$H12 -> 436634.55 | J29: =J$11*기준정보!$H12 -> 523961.46 | K29: =K$11*기준정보!$H12 -> 582179.4 | L29: =L$11*기준정보!$H12 -> 582179.4 | M29: =M$11*기준정보!$H12 -> 436634.55
E30: 자산비용 | F30: =F$11*기준정보!$H13 -> 90000 | G30: =G$11*기준정보!$H13 -> 297000 | H30: =H$11*기준정보!$H13 -> 352836 | I30: =I$11*기준정보!$H13 -> 436634.55 | J30: =J$11*기준정보!$H13 -> 523961.46 | K30: =K$11*기준정보!$H13 -> 582179.4 | L30: =L$11*기준정보!$H13 -> 582179.4 | M30: =M$11*기준정보!$H13 -> 436634.55
E31: 인적비용(4대보험등) | F31: =F$11*기준정보!$H14 -> 1440000 | G31: =G$11*기준정보!$H14 -> 4752000 | H31: =H$11*기준정보!$H14 -> 5645376 | I31: =I$11*기준정보!$H14 -> 6986152.8 | J31: =J$11*기준정보!$H14 -> 8383383.4 | K31: =K$11*기준정보!$H14 -> 9314870.4 | L31: =L$11*기준정보!$H14 -> 9314870.4 | M31: =M$11*기준정보!$H14 -> 6986152.8
E32: 기타판관비 | F32: =F$11*기준정보!$H15 -> 216000 | G32: =G$11*기준정보!$H15 -> 712800 | H32: =H$11*기준정보!$H15 -> 846806.4 | I32: =I$11*기준정보!$H15 -> 1047922.9 | J32: =J$11*기준정보!$H15 -> 1257507.5 | K32: =K$11*기준정보!$H15 -> 1397230.6 | L32: =L$11*기준정보!$H15 -> 1397230.6 | M32: =M$11*기준정보!$H15 -> 1047922.9
C33: 기타손익 | F33: =F34-F35 -> 36000 | G33: =G34-G35 -> 118800 | H33: =H34-H35 -> 141134.4 | I33: =I34-I35 -> 174653.82 | J33: =J34-J35 -> 209584.58 | K33: =K34-K35 -> 232871.76 | L33: =L34-L35 -> 232871.76 | M33: =M34-M35 -> 174653.82 | N33: =SUM(F33:M33) -> 1320570.1
E34: 기타수익 | F34: =F$11*기준정보!$H16 -> 180000 | G34: =G$11*기준정보!$H16 -> 594000 | H34: =H$11*기준정보!$H16 -> 705672 | I34: =I$11*기준정보!$H16 -> 873269.1 | J34: =J$11*기준정보!$H16 -> 1047922.9 | K34: =K$11*기준정보!$H16 -> 1164358.8 | L34: =L$11*기준정보!$H16 -> 1164358.8 | M34: =M$11*기준정보!$H16 -> 873269.1
E35: 기타비용 | F35: =F$11*기준정보!$H17 -> 144000 | G35: =G$11*기준정보!$H17 -> 475200 | H35: =H$11*기준정보!$H17 -> 564537.6 | I35: =I$11*기준정보!$H17 -> 698615.28 | J35: =J$11*기준정보!$H17 -> 838338.34 | K35: =K$11*기준정보!$H17 -> 931487.04 | L35: =L$11*기준정보!$H17 -> 931487.04 | M35: =M$11*기준정보!$H17 -> 698615.28
C36: 금융손익 | F36: =F37-F38 -> 90000 | G36: =G37-G38 -> 297000 | H36: =H37-H38 -> 352836 | I36: =I37-I38 -> 436634.55 | J36: =J37-J38 -> 523961.46 | K36: =K37-K38 -> 582179.4 | L36: =L37-L38 -> 582179.4 | M36: =M37-M38 -> 436634.55 | N36: =SUM(F36:M36) -> 3301425.4
E37: 금융수익 | F37: =F$11*기준정보!$H18 -> 450000 | G37: =G$11*기준정보!$H18 -> 1485000 | H37: =H$11*기준정보!$H18 -> 1764180 | I37: =I$11*기준정보!$H18 -> 2183172.8 | J37: =J$11*기준정보!$H18 -> 2619807.3 | K37: =K$11*기준정보!$H18 -> 2910897 | L37: =L$11*기준정보!$H18 -> 2910897 | M37: =M$11*기준정보!$H18 -> 2183172.8
E38: 금융비용 | F38: =F$11*기준정보!$H19 -> 360000 | G38: =G$11*기준정보!$H19 -> 1188000 | H38: =H$11*기준정보!$H19 -> 1411344 | I38: =I$11*기준정보!$H19 -> 1746538.2 | J38: =J$11*기준정보!$H19 -> 2095845.8 | K38: =K$11*기준정보!$H19 -> 2328717.6 | L38: =L$11*기준정보!$H19 -> 2328717.6 | M38: =M$11*기준정보!$H19 -> 1746538.2
C39: 세전이익 | F39: =F11-F12-F22+F33+F36 -> 14631867 | G39: =G11-G12-G22+G33+G36 -> 59923588 | H39: =H11-H12-H22+H33+H36 -> 73237974 | I39: =I11-I12-I22+I33+I36 -> 93141551 | J39: =J11-J12-J22+J33+J36 -> 1.1347075e+08 | K39: =K11-K12-K22+K33+K36 -> 1.2562323e+08 | L39: =L11-L12-L22+L33+L36 -> 1.2281663e+08 | M39: =M11-M12-M22+M33+M36 -> 84906092 | N39: =SUM(F39:M39) -> 6.8775168e+08
C40: 세전이익률 | F40: =F39/F11 -> 0.081288148 | G40: =G39/G11 -> 0.10088146 | H40: =H39/H11 -> 0.10378472 | I40: =I39/I11 -> 0.10665848 | J40: =J39/J11 -> 0.10828158 | K40: =K39/K11 -> 0.10789048 | L40: =L39/L11 -> 0.10548006 | M40: =M39/M11 -> 0.097227867 | N40: =N39/N11 -> 0.10415981

Sheet RFQ정보
B2: RFQ 정보(및 영업 추정 자료)
B4: 1. 기본 정보
B5: 프로젝트 코드 | C5: 고객사 | D5: 제품군 | E5: 제품 | F5: 차종 | G5: RFQ 접수일 | H5: 견적 제출일 | I5: 견적 제출 통화 | J5: 납품처
B6: 13007 | C6: HMC | D6: TM | E6: TM | F6: AA
B8: 2. 견적 대상 정보
B10: 프로젝트 코드(예시) | C10: 견적원가코드(예시) | D10: 기타
B11: 13007 | C11: 13007-TM-E01 | D11: TM 제품 AA 차종 1번 사양(국내 기본1사양)
B12: 13007 | C12: 13007-TM-E02 | D12: TM 제품 AA 차종 2번 사양(국내 기본2사양)
B13: 13007 | C13: 13007-TM-E03 | D13: TM 제품 AA 차종 3번 사양(국내 고급1사양
B14: 13007 | C14: 13007-TM-E04 | D14: TM 제품 AA 차종 4번 사양(국내 고급2사양)
B16: 3. 판가/수량 정보
B19: 견적원가코드(예시) | C19: Targer Price | D19: Market Price | E19: SOP | F19: EOP
B20: 13007-TM-E01 | C20: 600000 | D20: 600000 | E20: 2014.07 | F20: 2021.06
B21: 13007-TM-E02 | C21: 620000 | D21: 620000 | E21: 2014.07 | F21: 2021.06
B22: 13007-TM-E03 | C22: 700000 | D22: 700000 | E22: 2014.07 | F22: 2021.06
B23: 13007-TM-E04 | C23: 750000 | D23: 750000 | E23: 2014.07 | F23: 2021.06
B26: RFQ 수량
B27: 견적원가코드(예시) | C27: 2014 | D27: 2015 | E27: 2016 | F27: 2017 | G27: 2018 | H27: 2019 | I27: 2020 | J27: 2021 | K27: 합계
B28: 13007-TM-E01 | C28: 300 | D28: 1000 | E28: 1200 | F28: 1500 | G28: 1800 | H28: 2000 | I28: 2000 | J28: 1500 | K28: =SUM(C28:J28) -> 11300
B29: 13007-TM-E02 | C29: 300 | D29: 1000 | E29: 1200 | F29: 1500 | G29: 1800 | H29: 2000 | I29: 2000 | J29: 1500 | K29: =SUM(C29:J29) -> 11300
B30: 13007-TM-E03 | C30: 100 | D30: 300 | E30: 400 | F30: 400 | G30: 400 | H30: 400 | I30: 300 | J30: 200 | K30: =SUM(C30:J30) -> 2500
B31: 13007-TM-E04 | C31: 100 | D31: 300 | E31: 400 | F31: 400 | G31: 400 | H31: 400 | I31: 300 | J31: 200 | K31: =SUM(C31:J31) -> 2500
B33: TCI
B34: 견적원가코드(예시) | C34: 2014 | D34: 2015 | E34: 2016 | F34: 2017 | G34: 2018 | H34: 2019 | I34: 2020 | J34: 2021 | K34: 합계
B35: 13007-TM-E01 | D35: 0.01 | E35: 0.01 | F35: 0.01
B36: 13007-TM-E02 | D36: 0.01 | E36: 0.01 | F36: 0.01
B37: 13007-TM-E03 | D37: 0.01 | E37: 0.01 | F37: 0.01
B38: 13007-TM-E04 | D38: 0.01 | E38: 0.01 | F38: 0.01
B40: 연간 예상 판가_대당
B41: 견적원가코드(예시) | C41: 2014 | D41: 2015 | E41: 2016 | F41: 2017 | G41: 2018 | H41: 2019 | I41: 2020 | J41: 2021 | K41: 합계
B42: 13007-TM-E01 | C42: =C20 -> 600000 | D42: =C42*(1-D35) -> 594000 | E42: =D42*(1-E35) -> 588060 | F42: =E42*(1-F35) -> 582179.4 | G42: =F42*(1-G35) -> 582179.4 | H42: =G42*(1-H35) -> 582179.4 | I42: =H42*(1-I35) -> 582179.4 | J42: =I42*(1-J35) -> 582179.4
B43: 13007-TM-E02 | C43: =C21 -> 620000 | D43: =C43*(1-D36) -> 613800 | E43: =D43*(1-E36) -> 607662 | F43: =E43*(1-F36) -> 601585.38 | G43: =F43*(1-G36) -> 601585.38 | H43: =G43*(1-H36) -> 601585.38 | I43: =H43*(1-I36) -> 601585.38 | J43: =I43*(1-J36) -> 601585.38
B44: 13007-TM-E03 | C44: =C22 -> 700000 | D44: =C44*(1-D37) -> 693000 | E44: =D44*(1-E37) -> 686070 | F44: =E44*(1-F37) -> 679209.3 | G44: =F44*(1-G37) -> 679209.3 | H44: =G44*(1-H37) -> 679209.3 | I44: =H44*(1-I37) -> 679209.3 | J44: =I44*(1-J37) -> 679209.3
B45: 13007-TM-E04 | C45: =C23 -> 750000 | D45: =C45*(1-D38) -> 742500 | E45: =D45*(1-E38) -> 735075 | F45: =E45*(1-F38) -> 727724.25 | G45: =F45*(1-G38) -> 727724.25 | H45: =G45*(1-H38) -> 727724.25 | I45: =H45*(1-I38) -> 727724.25 | J45: =I45*(1-J38) -> 727724.25
B47: 연간 예상 판가_total
B48: 견적원가코드(예시) | C48: 2014 | D48: 2015 | E48: 2016 | F48: 2017 | G48: 2018 | H48: 2019 | I48: 2020 | J48: 2021 | K48: 합계
B49: 13007-TM-E01 | C49: =C42*C28 -> 180000000 | D49: =D42*D28 -> 594000000 | E49: =E42*E28 -> 705672000 | F49: =F42*F28 -> 873269100 | G49: =G42*G28 -> 1047922920 | H49: =H42*H28 -> 1164358800 | I49: =I42*I28 -> 1164358800 | J49: =J42*J28 -> 873269100
B50: 13007-TM-E02 | C50: =C43*C29 -> 186000000 | D50: =D43*D29 -> 613800000 | E50: =E43*E29 -> 729194400 | F50: =F43*F29 -> 902378070 | G50: =G43*G29 -> 1082853684 | H50: =H43*H29 -> 1203170760 | I50: =I43*I29 -> 1203170760 | J50: =J43*J29 -> 902378070
B51: 13007-TM-E03 | C51: =C44*C30 -> 70000000 | D51: =D44*D30 -> 207900000 | E51: =E44*E30 -> 274428000 | F51: =F44*F30 -> 271683720 | G51: =G44*G30 -> 271683720 | H51: =H44*H30 -> 271683720 | I51: =I44*I30 -> 203762790 | J51: =J44*J30 -> 135841860
B52: 13007-TM-E04 | C52: =C45*C31 -> 75000000 | D52: =D45*D31 -> 222750000 | E52: =E45*E31 -> 294030000 | F52: =F45*F31 -> 291089700 | G52: =G45*G31 -> 291089700 | H52: =H45*H31 -> 291089700 | I52: =I45*I31 -> 218317275 | J52: =J45*J31 -> 145544850
...

Sheet master list(견적BOM)
B2: 원가코드 | C2: 13007-TM-E01
B3: 재료비 loss율 | C3: 0.011
C5: 참조제품 | D5: 신제품 | F5: 신규여부 검증 (PIMS 기준) | H5: 단가
B6: 구분 | C6: 품번(Ref. 제품) | D6: 품번 | E6: 품명 | G6: 수량 | H6: 통화 | I6: 설계원가 | J6: 구매(or PIMS) | K6: 원가관리 | L6: 계
B7: C/O | C7: 12345 | D7: 12345 | E7: 가 | F7: C/O | G7: 4 | H7: KRW | J7: 25000 | K7: =J7 -> 25000 | L7: =IF(H7="KRW",G7*K7,(IF(H7="USD",G7*K7*기준정보!$F$43,0))) -> 100000
B8: C/O | C8: 12346 | D8: 12346 | E8: 나 | F8: C/O | G8: 4 | H8: KRW | J8: 10000 | K8: =J8 -> 10000 | L8: =IF(H8="KRW",G8*K8,(IF(H8="USD",G8*K8*기준정보!$F$43,0))) -> 40000
B9: C/O | C9: 12347 | D9: 12347 | E9: 다 | F9: C/O | G9: 2 | H9: KRW | J9: 1000 | K9: =J9 -> 1000 | L9: =IF(H9="KRW",G9*K9,(IF(H9="USD",G9*K9*기준정보!$F$43,0))) -> 2000
B10: 신규 | C10: 12348 | D10: 12348 | E10: 라 | F10: C/O | G10: 2 | H10: USD | J10: 80 | K10: =J10 -> 80 | L10: =IF(H10="KRW",G10*K10,(IF(H10="USD",G10*K10*기준정보!$F$43,0))) -> 176000
B11: C/O | C11: 12349 | D11: 12349 | E11: 마 | F11: C/O | G11: 1 | H11: KRW | J11: 8000 | K11: =J11 -> 8000 | L11: =IF(H11="KRW",G11*K11,(IF(H11="USD",G11*K11*기준정보!$F$43,0))) -> 8000
B12: 신규 | C12: 12350 | D12: 12350 | E12: 바' | F12: C/O | G12: 4 | H12: KRW | I12: 2000 | J12: 2500 | K12: =J12 -> 2500 | L12: =IF(H12="KRW",G12*K12,(IF(H12="USD",G12*K12*기준정보!$F$43,0))) -> 10000
B13: 신규 | C13: 12351 | D13: 12351b | E13: 사' | F13: 신규 | G13: 1 | H13: KRW | I13: 5000 | J13: 5300 | K13: =J13 -> 5300 | L13: =IF(H13="KRW",G13*K13,(IF(H13="USD",G13*K13*기준정보!$F$43,0))) -> 5300
B14: 신규 | C14: 12352 | D14: 12352c | E14: 아' | F14: 신규 | G14: 2 | H14: USD | I14: 50 | J14: 60 | K14: =J14 -> 60 | L14: =IF(H14="KRW",G14*K14,(IF(H14="USD",G14*K14*기준정보!$F$43,0))) -> 132000
B15: 총계 | L15: =SUM(L7:L14) -> 473300
K17: 총 재료비 | L17: =L15/(1-C3) -> 478564.21
B19: 대당 예상 재료비(13007-TM-E01)
B20: 견적원가코드(예시) | C20: 2014 | D20: 2015 | E20: 2016 | F20: 2017 | G20: 2018 | H20: 2019 | I20: 2020 | J20: 2021 | K20: 합계
B21: 13007-TM-E01 | C21: =L17 -> 478564.21 | D21: =C21*(1-RFQ정보!D35) -> 473778.56 | E21: =D21*(1-RFQ정보!E35) -> 469040.78 | F21: =E21*(1-RFQ정보!F35) -> 464350.37 | G21: =F21*(1-RFQ정보!G35) -> 464350.37 | H21: =G21*(1-RFQ정보!H35) -> 464350.37 | I21: =H21*(1-RFQ정보!I35) -> 464350.37 | J21: =I21*(1-RFQ정보!J35) -> 464350.37
B23: 연간 예상 재료비(13007-TM-E01)
B24: 견적원가코드(예시) | C24: 2014 | D24: 2015 | E24: 2016 | F24: 2017 | G24: 2018 | H24: 2019 | I24: 2020 | J24: 2021 | K24: 합계
B25: 13007-TM-E01 | C25: =C21*RFQ정보!C28 -> 1.4356926e+08 | D25: =D21*RFQ정보!D28 -> 4.7377856e+08 | E25: =E21*RFQ정보!E28 -> 5.6284893e+08 | F25: =F21*RFQ정보!F28 -> 6.9652556e+08 | G25: =G21*RFQ정보!G28 -> 8.3583067e+08 | H25: =H21*RFQ정보!H28 -> 9.2870074e+08 | I25: =I21*RFQ정보!I28 -> 9.2870074e+08 | J25: =J21*RFQ정보!J28 -> 6.9652556e+08

Sheet 원가산출 정보
B2: 연도별 비율
C4: 기준연도 | D4: 항목 | E4: 값
C5: 2013 | D5: 임금인상률 | E5: 0.05
C6: 2013 | D6: 물가상승률 | E6: 0.04
B11: 생산라인 정보
C13: 원가코드 | D13: 1307-TM-E01
B14: 기존 라인
B15: 구분 | C15: 기준연도 (실적연도) | D15: 라인 코드 | E15: 라인 명 | F15: 공장 | G15: 연간 total C/T | H15: 내용연수 | I15: 취득연월 | J15: C/T | K15: C/T 당 원가 | P15: 총계
K16: 노무비 | L16: 생산직접비 | M16: 감가상각비 | N16: 인건비성경비 | O16: 기타경비
B17: 기존 | C17: 2012 | D17: 65432 | E17: 가공라인 | F17: 서산공장 | G17: 1000000000 | H17: 10 | I17: 2013.01 | J17: 100 | K17: 100 | L17: 30 | M17: 10 | N17: 40 | O17: 10
B19: 총계 | K19: =$J$17*K17 -> 10000 | L19: =$J$17*L17 -> 3000 | M19: =$J$17*M17 -> 1000 | N19: =$J$17*N17 -> 4000 | O19: =$J$17*O17 -> 1000
B20: SOP | C20: 2014 | K20: =K19*(1+$E$5)^($C$20-$C$17) -> 11025 | L20: =L19*(1+$E$6)^($C$20-$C$17) -> 3244.8 | M20: =M19 -> 1000 | N20: =N19*(1+$E$5)^($C$20-$C$17) -> 4410 | O20: =O19*(1+$E$6)^($C$20-$C$17) -> 1081.6
B22: 신규 라인
B23: 구분 | C23: 기준연도 | D23: 라인 코드 | E23: 라인 명 | F23: 공장 | G23: 투자금액 | H23: 내용연수 | I23: 취득연월 | J23: C/T | K23: C/T 당 원가 | P23: 총계
K24: 노무비 | L24: 생산직접비 | M24: 감가상각비 | N24: 인건비성경비 | O24: 기타경비
B25: 신규 | C25: 2014 | D25: 65433 | E25: 조립라인 | F25: 서산공장 | G25: 200000000 | H25: 10 | I25: 2014.07 | J25: 20 | K25: 30 | L25: 20 | N25: 15 | O25: 5
B27: 총계 | K27: =$J$25*K25 -> 600 | L27: =$J$25*L25 -> 400 | N27: =$J$25*N25 -> 300 | O27: =$J$25*O25 -> 100
B28: SOP | C28: 2014 | K28: =K27*(1+$E$5)^($C$28-$C$25) -> 600 | L28: =L27*(1+$E$6)^($C$28-$C$25) -> 400 | N28: =N27*(1+$E$5)^($C$28-$C$25) -> 300 | O28: =O27*(1+$E$6)^($C$28-$C$25) -> 100
B30: 제조원가 합계
K31: 노무비 | L31: 생산직접비 | M31: 감가상각비(기존) | N31: 인건비성경비 | O31: 기타경비
K32: =K20+K28 -> 11625 | L32: =L20+L28 -> 3644.8 | M32: =M20 -> 1000 | N32: =N20+N28 -> 4710 | O32: =O20+O28 -> 1181.6
C35: 대당 예상 제조원가(13007-TM-E01)
C36: 견적원가코드(예시) | D36: 2014 | E36: 2015 | F36: 2016 | G36: 2017 | H36: 2018 | I36: 2019 | J36: 2020 | K36: 2021 | L36: 합계
C37: 노무비 | D37: =K32*(1+E5)^($C$20-$C$17) -> 12816.562 | E37: =D37*(1+$E$5) -> 13457.391 | F37: =E37*(1+$E$5) -> 14130.26 | G37: =F37*(1+$E$5) -> 14836.773 | H37: =G37*(1+$E$5) -> 15578.612 | I37: =H37*(1+$E$5) -> 16357.542 | J37: =I37*(1+$E$5) -> 17175.42 | K37: =J37*(1+$E$5) -> 18034.191
C38: 생산직접비 | D38: =L32*(1+E6)^($C$20-$C$17) -> 3942.2157 | E38: =D38*(1+$E$6) -> 4099.9043 | F38: =E38*(1+$E$6) -> 4263.9005 | G38: =F38*(1+$E$6) -> 4434.4565 | H38: =G38*(1+$E$6) -> 4611.8348 | I38: =H38*(1+$E$6) -> 4796.3081 | J38: =I38*(1+$E$6) -> 4988.1605 | K38: =J38*(1+$E$6) -> 5187.6869
C39: 감가상각비 | D39: =M32 -> 1000 | E39: =D39 -> 1000 | F39: =E39 -> 1000 | G39: =F39 -> 1000 | H39: =G39 -> 1000 | I39: =H39 -> 1000 | J39: =I39 -> 1000 | K39: =J39 -> 1000
C40: 인건비성경비 | D40: =N32*(1+E5)^($C$20-$C$17) -> 5192.775 | E40: =D40*(1+$E$5) -> 5452.4138 | F40: =E40*(1+$E$5) -> 5725.0344 | G40: =F40*(1+$E$5) -> 6011.2862 | H40: =G40*(1+$E$5) -> 6311.8505 | I40: =H40*(1+$E$5) -> 6627.443 | J40: =I40*(1+$E$5) -> 6958.8151 | K40: =J40*(1+$E$5) -> 7306.7559
C41: 기타경비 | D41: =O32*(1+E6)^($C$20-$C$17) -> 1278.0186 | E41: =D41*(1+$E$6) -> 1329.1393 | F41: =E41*(1+$E$6) -> 1382.3049 | G41: =F41*(1+$E$6) -> 1437.5971 | H41: =G41*(1+$E$6) -> 1495.101 | I41: =H41*(1+$E$6) -> 1554.905 | J41: =I41*(1+$E$6) -> 1617.1012 | K41: =J41*(1+$E$6) -> 1681.7852
C43: 신규라인 연간 감가상각비(13007-TM-E01)
C44: 견적원가코드(예시) | D44: 2014 | E44: 2015 | F44: 2016 | G44: 2017 | H44: 2018 | I44: 2019 | J44: 2020 | K44: 2021 | L44: 합계
C45: 감가상각비(신규) | D45: =G25/H25*6/12 -> 10000000 | E45: =G25/H25 -> 20000000 | F45: =E45 -> 20000000 | G45: =F45 -> 20000000 | H45: =G45 -> 20000000 | I45: =H45 -> 20000000 | J45: =I45 -> 20000000 | K45: =J45 -> 20000000
C48: 연간 예상 제조원가(13007-TM-E01)
C49: 견적원가코드(예시) | D49: 2014 | E49: 2015 | F49: 2016 | G49: 2017 | H49: 2018 | I49: 2019 | J49: 2020 | K49: 2021 | L49: 합계
C50: 노무비 | D50: =D37*RFQ정보!C$28 -> 3844968.8 | E50: =E37*RFQ정보!D$28 -> 13457391 | F50: =F37*RFQ정보!E$28 -> 16956312 | G50: =G37*RFQ정보!F$28 -> 22255160 | H50: =H37*RFQ정보!G$28 -> 28041501 | I50: =I37*RFQ정보!H$28 -> 32715085 | J50: =J37*RFQ정보!I$28 -> 34350839 | K50: =K37*RFQ정보!J$28 -> 27051286
C51: 생산직접비 | D51: =D38*RFQ정보!C$28 -> 1182664.7 | E51: =E38*RFQ정보!D$28 -> 4099904.3 | F51: =F38*RFQ정보!E$28 -> 5116680.6 | G51: =G38*RFQ정보!F$28 -> 6651684.7 | H51: =H38*RFQ정보!G$28 -> 8301302.6 | I51: =I38*RFQ정보!H$28 -> 9592616.3 | J51: =J38*RFQ정보!I$28 -> 9976320.9 | K51: =K38*RFQ정보!J$28 -> 7781530.3
C52: 감가상각비 | D52: =D39*RFQ정보!C$28+D45 -> 10300000 | E52: =E39*RFQ정보!D$28+E45 -> 21000000 | F52: =F39*RFQ정보!E$28+F45 -> 21200000 | G52: =G39*RFQ정보!F$28+G45 -> 21500000 | H52: =H39*RFQ정보!G$28+H45 -> 21800000 | I52: =I39*RFQ정보!H$28+I45 -> 22000000 | J52: =J39*RFQ정보!I$28+J45 -> 22000000 | K52: =K39*RFQ정보!J$28+K45 -> 21500000
C53: 인건비성경비 | D53: =D40*RFQ정보!C$28 -> 1557832.5 | E53: =E40*RFQ정보!D$28 -> 5452413.8 | F53: =F40*RFQ정보!E$28 -> 6870041.3 | G53: =G40*RFQ정보!F$28 -> 9016929.2 | H53: =H40*RFQ정보!G$28 -> 11361331 | I53: =I40*RFQ정보!H$28 -> 13254886 | J53: =J40*RFQ정보!I$28 -> 13917630 | K53: =K40*RFQ정보!J$28 -> 10960134
C54: 기타경비 | D54: =D41*RFQ정보!C$28 -> 383405.57 | E54: =E41*RFQ정보!D$28 -> 1329139.3 | F54: =F41*RFQ정보!E$28 -> 1658765.8 | G54: =G41*RFQ정보!F$28 -> 2156395.6 | H54: =H41*RFQ정보!G$28 -> 2691181.7 | I54: =I41*RFQ정보!H$28 -> 3109810 | J54: =J41*RFQ정보!I$28 -> 3234202.4 | K54: =K41*RFQ정보!J$28 -> 2522677.9

Sheet 기준정보
B3: 사업실적 비율
B6: 순번 | C6: 적용연도 | D6: 법인코드 | E6: 법인명 | F6: 원가 CoA | G6: 원가 CoA 계정명 | H6: 비율
B7: 1 | C7: 2013 | E7: 다이모스 | F7: 3010 | G7: 판관인건비 | H7: 0.005
B8: 2 | C8: 2013 | E8: 다이모스 | F8: 3110 | G8: 운반비 | H8: 0.003
B9: 3 | C9: 2013 | E9: 다이모스 | F9: 3120 | G9: 수출비 | H9: 0.001
B10: 4 | C10: 2013 | E10: 다이모스 | F10: 3040 | G10: 품질보증비 | H10: 0.003
B11: 5 | C11: 2013 | E11: 다이모스 | F11: 3050 | G11: 광고선전비 | H11: 0.002
B12: 6 | C12: 2013 | E12: 다이모스 | F12: 3060 | G12: 연구비 | H12: 0.0005
B13: 7 | C13: 2013 | E13: 다이모스 | F13: 3070 | G13: 자산비용 | H13: 0.0005
B14: 8 | C14: 2013 | E14: 다이모스 | F14: 3080 | G14: 인적비용(4대보험등) | H14: 0.008
B15: 9 | C15: 2013 | E15: 다이모스 | F15: 3090 | G15: 기타판관비 | H15: 0.0012
B16: 10 | C16: 2013 | E16: 다이모스 | F16: 4010 | G16: 기타수익 | H16: 0.001
B17: 11 | C17: 2013 | E17: 다이모스 | F17: 4020 | G17: 기타비용 | H17: 0.0008
B18: 12 | C18: 2013 | E18: 다이모스 | F18: 5010 | G18: 금융수익 | H18: 0.0025
B19: 13 | C19: 2013 | E19: 다이모스 | F19: 5020 | G19: 금융비용 | H19: 0.002
B23: 견적 단계
B25: 순번 | C25: Code | D25: 표준 Task 명 | E25: 소요일 | F25: 주관부서 | G25: 선행업무 | H25: 변경자 | I25: 변경일
B26: 1 | C26: G10 | D26: 견적원가 Code 생성 | E26: 1 | F26: 영업 | I26: YYYYMMDD
B27: 2 | C27: G20 | D27: 견적원가 대상 등록 | E27: 1 | F27: 영업 | G27: G10 | I27: YYYYMMDD
B28: 3 | C28: G30 | D28: BOM(master list)작성 | E28: 5 | F28: 설계 | G28: G20 | I28: YYYYMMDD
B29: 4 | C29: G40 | D29: 신규자재 설계원가 작성 | E29: 4 | F29: 설계원가 | G29: G30 | I29: YYYYMMDD
B30: 5 | C30: G50 | D30: 신규자재 구매추정가 작성 | E30: 4 | F30: 구매 | G30: G30 | I30: YYYYMMDD
B31: 6 | C31: G60 | D31: 재료비 단가 검토 | E31: 3 | F31: 원가 | G31: G40 | I31: YYYYMMDD
B32: 7 | C32: G70 | D32: 인원/투자비 산정 | E32: 9 | F32: 생기 | G32: G20 | I32: YYYYMMDD
B33: 8 | C33: G80 | D33: 견적원가 산출 및 수익성 분석 | E33: 2 | F33: 원가 | G33: G60 | I33: YYYYMMDD
B36: 환율 정보
B38: 순번 | C38: 적용연도 | D38: From 통화 | E38: To 통화 | F38: 환율
B39: 1 | C39: 2012 | D39: USD | E39: KRW | F39: 1200
B40: 2 | C40: 2012 | D40: EUR | E40: KRW | F40: 1350
B41: 3 | C41: 2012 | D41: JPY | E41: KRW | F41: 1500
B42: 4 | C42: … | D42: … | E42: … | F42: …
B43: 5 | C43: 2013 | D43: USD | E43: KRW | F43: 1100
B44: 6 | C44: 2013 | D44: EUR | E44: KRW | F44: 1400
B45: 7 | C45: 2013 | D45: JPY | E45: KRW | F45: 1600
B46: 8 | C46: … | D46: … | E46: … | F46: …
B47: 9
B48: 10
B49: 11
B50: 12

Sheet 목표

Sheet 목표수익률
